<sdf version='1.7'>
  <world name='default'>
    <model name='ground_plane'>
      <static>1</static>
      <link name='link'>
        <collision name='collision'>
          <geometry>
            <plane>
              <normal>0 0 1</normal>
              <size>100 100</size>
            </plane>
          </geometry>
          <surface>
            <friction>
              <ode>
                <mu>100</mu>
                <mu2>50</mu2>
              </ode>
              <torsional>
                <ode/>
              </torsional>
            </friction>
            <contact>
              <ode/>
            </contact>
            <bounce/>
          </surface>
          <max_contacts>10</max_contacts>
        </collision>
        <visual name='visual'>
          <cast_shadows>0</cast_shadows>
          <geometry>
            <plane>
              <normal>0 0 1</normal>
              <size>100 100</size>
            </plane>
          </geometry>
          <material>
            <script>
              <uri>file://media/materials/scripts/gazebo.material</uri>
              <name>Gazebo/Grey</name>
            </script>
          </material>
        </visual>
        <self_collide>0</self_collide>
        <enable_wind>0</enable_wind>
        <kinematic>0</kinematic>
      </link>
    </model>
    <light name='sun' type='directional'>
      <cast_shadows>1</cast_shadows>
      <pose>0 0 10 0 -0 0</pose>
      <diffuse>0.8 0.8 0.8 1</diffuse>
      <specular>0.2 0.2 0.2 1</specular>
      <attenuation>
        <range>1000</range>
        <constant>0.9</constant>
        <linear>0.01</linear>
        <quadratic>0.001</quadratic>
      </attenuation>
      <direction>-0.5 0.1 -0.9</direction>
      <spot>
        <inner_angle>0</inner_angle>
        <outer_angle>0</outer_angle>
        <falloff>0</falloff>
      </spot>
    </light>
    <scene>
      <shadows>0</shadows>
      <ambient>0.4 0.4 0.4 1</ambient>
      <background>0.7 0.7 0.7 1</background>
    </scene>
    <gui fullscreen='0'>
      <camera name='user_camera'>
        <pose>18.7048 -4.17587 12.6192 0 0.525803 3.13358</pose>
        <view_controller>orbit</view_controller>
        <projection_type>perspective</projection_type>
      </camera>
    </gui>
    <physics type='ode'>
      <real_time_update_rate>1000</real_time_update_rate>
      <max_step_size>0.001</max_step_size>
      <real_time_factor>1</real_time_factor>
      <ode>
        <solver>
          <type>quick</type>
          <iters>150</iters>
          <precon_iters>0</precon_iters>
          <sor>1.4</sor>
          <use_dynamic_moi_rescaling>1</use_dynamic_moi_rescaling>
        </solver>
        <constraints>
          <cfm>1e-05</cfm>
          <erp>0.2</erp>
          <contact_max_correcting_vel>2000</contact_max_correcting_vel>
          <contact_surface_layer>0.01</contact_surface_layer>
        </constraints>
      </ode>
    </physics>
    <gravity>0 0 -9.8</gravity>
    <magnetic_field>6e-06 2.3e-05 -4.2e-05</magnetic_field>
    <atmosphere type='adiabatic'/>
    <wind/>
    <spherical_coordinates>
      <surface_model>EARTH_WGS84</surface_model>
      <latitude_deg>0</latitude_deg>
      <longitude_deg>0</longitude_deg>
      <elevation>0</elevation>
      <heading_deg>0</heading_deg>
    </spherical_coordinates>
    <model name='Coffee_Shop_Model_V3'>
      <link name='link_0'>
        <inertial>
          <mass>1</mass>
          <inertia>
            <ixx>0.166667</ixx>
            <ixy>0</ixy>
            <ixz>0</ixz>
            <iyy>0.166667</iyy>
            <iyz>0</iyz>
            <izz>0.166667</izz>
          </inertia>
          <pose>0 0 0 0 -0 0</pose>
        </inertial>
        <pose>0.059933 1.25129 0.589943 1.57072 -0.004244 -1.55352</pose>
        <visual name='visual'>
          <pose>0 0 0 0 -0 0</pose>
          <geometry>
            <mesh>
              <uri>/project_2_WS/src/barista_robot/worlds/coffee_machine_model/meshes/base_link.STL</uri>
              <scale>1 1 1</scale>
            </mesh>
          </geometry>
          <material>
            <lighting>1</lighting>
            <script>
              <uri>file://media/materials/scripts/gazebo.material</uri>
              <name>Gazebo/Grey</name>
            </script>
            <shader type='pixel'/>
          </material>
          <transparency>0</transparency>
          <cast_shadows>1</cast_shadows>
        </visual>
        <collision name='collision'>
          <laser_retro>0</laser_retro>
          <max_contacts>10</max_contacts>
          <pose>0 0 0 0 -0 0</pose>
          <geometry>
            <mesh>
              <uri>/project_2_WS/src/barista_robot/worlds/coffee_machine_model/meshes/base_link.STL</uri>
              <scale>1 1 1</scale>
            </mesh>
          </geometry>
          <surface>
            <friction>
              <ode>
                <mu>1</mu>
                <mu2>1</mu2>
                <fdir1>0 0 0</fdir1>
                <slip1>0</slip1>
                <slip2>0</slip2>
              </ode>
              <torsional>
                <coefficient>1</coefficient>
                <patch_radius>0</patch_radius>
                <surface_radius>0</surface_radius>
                <use_patch_radius>1</use_patch_radius>
                <ode>
                  <slip>0</slip>
                </ode>
              </torsional>
            </friction>
            <bounce>
              <restitution_coefficient>0</restitution_coefficient>
              <threshold>1e+06</threshold>
            </bounce>
            <contact>
              <collide_without_contact>0</collide_without_contact>
              <collide_without_contact_bitmask>1</collide_without_contact_bitmask>
              <collide_bitmask>1</collide_bitmask>
              <ode>
                <soft_cfm>0</soft_cfm>
                <soft_erp>0.2</soft_erp>
                <kp>1e+13</kp>
                <kd>1</kd>
                <max_vel>0.01</max_vel>
                <min_depth>0</min_depth>
              </ode>
              <bullet>
                <split_impulse>1</split_impulse>
                <split_impulse_penetration_threshold>-0.01</split_impulse_penetration_threshold>
                <soft_cfm>0</soft_cfm>
                <soft_erp>0.2</soft_erp>
                <kp>1e+13</kp>
                <kd>1</kd>
              </bullet>
            </contact>
          </surface>
        </collision>
        <self_collide>0</self_collide>
        <enable_wind>0</enable_wind>
        <kinematic>0</kinematic>
      </link>
      <link name='link_1'>
        <inertial>
          <mass>1</mass>
          <inertia>
            <ixx>0.166667</ixx>
            <ixy>0</ixy>
            <ixz>0</ixz>
            <iyy>0.166667</iyy>
            <iyz>0</iyz>
            <izz>0.166667</izz>
          </inertia>
          <pose>0 0 0 0 -0 0</pose>
        </inertial>
        <pose>-1.5311 -0.183448 0.584686 1.56674 -0 0</pose>
        <visual name='visual'>
          <pose>0 0 0 0 -0 0</pose>
          <geometry>
            <mesh>
              <uri>/project_2_WS/src/barista_robot/worlds/milk_machine_model/meshes/base_link.STL</uri>
              <scale>1 1 1</scale>
            </mesh>
          </geometry>
          <material>
            <lighting>1</lighting>
            <script>
              <uri>file://media/materials/scripts/gazebo.material</uri>
              <name>Gazebo/Grey</name>
            </script>
            <shader type='pixel'/>
          </material>
          <transparency>0</transparency>
          <cast_shadows>1</cast_shadows>
        </visual>
        <collision name='collision'>
          <laser_retro>0</laser_retro>
          <max_contacts>10</max_contacts>
          <pose>0 0 0 0 -0 0</pose>
          <geometry>
            <mesh>
              <uri>/project_2_WS/src/barista_robot/worlds/milk_machine_model/meshes/base_link.STL</uri>
              <scale>1 1 1</scale>
            </mesh>
          </geometry>
          <surface>
            <friction>
              <ode>
                <mu>1</mu>
                <mu2>1</mu2>
                <fdir1>0 0 0</fdir1>
                <slip1>0</slip1>
                <slip2>0</slip2>
              </ode>
              <torsional>
                <coefficient>1</coefficient>
                <patch_radius>0</patch_radius>
                <surface_radius>0</surface_radius>
                <use_patch_radius>1</use_patch_radius>
                <ode>
                  <slip>0</slip>
                </ode>
              </torsional>
            </friction>
            <bounce>
              <restitution_coefficient>0</restitution_coefficient>
              <threshold>1e+06</threshold>
            </bounce>
            <contact>
              <collide_without_contact>0</collide_without_contact>
              <collide_without_contact_bitmask>1</collide_without_contact_bitmask>
              <collide_bitmask>1</collide_bitmask>
              <ode>
                <soft_cfm>0</soft_cfm>
                <soft_erp>0.2</soft_erp>
                <kp>1e+13</kp>
                <kd>1</kd>
                <max_vel>0.01</max_vel>
                <min_depth>0</min_depth>
              </ode>
              <bullet>
                <split_impulse>1</split_impulse>
                <split_impulse_penetration_threshold>-0.01</split_impulse_penetration_threshold>
                <soft_cfm>0</soft_cfm>
                <soft_erp>0.2</soft_erp>
                <kp>1e+13</kp>
                <kd>1</kd>
              </bullet>
            </contact>
          </surface>
        </collision>
        <self_collide>0</self_collide>
        <enable_wind>0</enable_wind>
        <kinematic>0</kinematic>
      </link>
      <link name='link_2'>
        <inertial>
          <mass>1</mass>
          <inertia>
            <ixx>0.166667</ixx>
            <ixy>0</ixy>
            <ixz>0</ixz>
            <iyy>0.166667</iyy>
            <iyz>0</iyz>
            <izz>0.166667</izz>
          </inertia>
          <pose>0 0 0 0 -0 0</pose>
        </inertial>
        <pose>1.2927 -0.079798 0.581572 0 -0 0</pose>
        <visual name='visual'>
          <pose>0 0 0 0 -0 0</pose>
          <geometry>
            <mesh>
              <uri>/project_2_WS/src/barista_robot/worlds/coffee_cup_with_rim_model/meshes/base_link.STL</uri>
              <scale>1 1 1</scale>
            </mesh>
          </geometry>
          <material>
            <lighting>1</lighting>
            <script>
              <uri>file://media/materials/scripts/gazebo.material</uri>
              <name>Gazebo/Grey</name>
            </script>
            <shader type='pixel'/>
          </material>
          <transparency>0</transparency>
          <cast_shadows>1</cast_shadows>
        </visual>
        <collision name='collision'>
          <laser_retro>0</laser_retro>
          <max_contacts>10</max_contacts>
          <pose>0 0 0 0 -0 0</pose>
          <geometry>
            <mesh>
              <uri>/project_2_WS/src/barista_robot/worlds/coffee_cup_with_rim_model/meshes/base_link.STL</uri>
              <scale>1 1 1</scale>
            </mesh>
          </geometry>
          <surface>
            <friction>
              <ode>
                <mu>1</mu>
                <mu2>1</mu2>
                <fdir1>0 0 0</fdir1>
                <slip1>0</slip1>
                <slip2>0</slip2>
              </ode>
              <torsional>
                <coefficient>1</coefficient>
                <patch_radius>0</patch_radius>
                <surface_radius>0</surface_radius>
                <use_patch_radius>1</use_patch_radius>
                <ode>
                  <slip>0</slip>
                </ode>
              </torsional>
            </friction>
            <bounce>
              <restitution_coefficient>0</restitution_coefficient>
              <threshold>1e+06</threshold>
            </bounce>
            <contact>
              <collide_without_contact>0</collide_without_contact>
              <collide_without_contact_bitmask>1</collide_without_contact_bitmask>
              <collide_bitmask>1</collide_bitmask>
              <ode>
                <soft_cfm>0</soft_cfm>
                <soft_erp>0.2</soft_erp>
                <kp>1e+13</kp>
                <kd>1</kd>
                <max_vel>0.01</max_vel>
                <min_depth>0</min_depth>
              </ode>
              <bullet>
                <split_impulse>1</split_impulse>
                <split_impulse_penetration_threshold>-0.01</split_impulse_penetration_threshold>
                <soft_cfm>0</soft_cfm>
                <soft_erp>0.2</soft_erp>
                <kp>1e+13</kp>
                <kd>1</kd>
              </bullet>
            </contact>
          </surface>
        </collision>
        <self_collide>0</self_collide>
        <enable_wind>0</enable_wind>
        <kinematic>0</kinematic>
      </link>
      <model name='table'>
        <static>1</static>
        <link name='link'>
          <collision name='surface'>
            <pose>0 0 1 0 -0 0</pose>
            <geometry>
              <box>
                <size>1.5 0.8 0.03</size>
              </box>
            </geometry>
            <surface>
              <friction>
                <ode>
                  <mu>0.6</mu>
                  <mu2>0.6</mu2>
                </ode>
                <torsional>
                  <ode/>
                </torsional>
              </friction>
              <contact>
                <ode/>
              </contact>
              <bounce/>
            </surface>
            <max_contacts>10</max_contacts>
          </collision>
          <visual name='visual1'>
            <pose>0 0 1 0 -0 0</pose>
            <geometry>
              <box>
                <size>1.5 0.8 0.03</size>
              </box>
            </geometry>
            <material>
              <script>
                <uri>file://media/materials/scripts/gazebo.material</uri>
                <name>Gazebo/Wood</name>
              </script>
            </material>
          </visual>
          <collision name='front_left_leg'>
            <pose>0.68 0.38 0.5 0 -0 0</pose>
            <geometry>
              <cylinder>
                <radius>0.02</radius>
                <length>1</length>
              </cylinder>
            </geometry>
            <max_contacts>10</max_contacts>
            <surface>
              <contact>
                <ode/>
              </contact>
              <bounce/>
              <friction>
                <torsional>
                  <ode/>
                </torsional>
                <ode/>
              </friction>
            </surface>
          </collision>
          <visual name='front_left_leg'>
            <pose>0.68 0.38 0.5 0 -0 0</pose>
            <geometry>
              <cylinder>
                <radius>0.02</radius>
                <length>1</length>
              </cylinder>
            </geometry>
            <material>
              <script>
                <uri>file://media/materials/scripts/gazebo.material</uri>
                <name>Gazebo/Grey</name>
              </script>
            </material>
          </visual>
          <collision name='front_right_leg'>
            <pose>0.68 -0.38 0.5 0 -0 0</pose>
            <geometry>
              <cylinder>
                <radius>0.02</radius>
                <length>1</length>
              </cylinder>
            </geometry>
            <max_contacts>10</max_contacts>
            <surface>
              <contact>
                <ode/>
              </contact>
              <bounce/>
              <friction>
                <torsional>
                  <ode/>
                </torsional>
                <ode/>
              </friction>
            </surface>
          </collision>
          <visual name='front_right_leg'>
            <pose>0.68 -0.38 0.5 0 -0 0</pose>
            <geometry>
              <cylinder>
                <radius>0.02</radius>
                <length>1</length>
              </cylinder>
            </geometry>
            <material>
              <script>
                <uri>file://media/materials/scripts/gazebo.material</uri>
                <name>Gazebo/Grey</name>
              </script>
            </material>
          </visual>
          <collision name='back_right_leg'>
            <pose>-0.68 -0.38 0.5 0 -0 0</pose>
            <geometry>
              <cylinder>
                <radius>0.02</radius>
                <length>1</length>
              </cylinder>
            </geometry>
            <max_contacts>10</max_contacts>
            <surface>
              <contact>
                <ode/>
              </contact>
              <bounce/>
              <friction>
                <torsional>
                  <ode/>
                </torsional>
                <ode/>
              </friction>
            </surface>
          </collision>
          <visual name='back_right_leg'>
            <pose>-0.68 -0.38 0.5 0 -0 0</pose>
            <geometry>
              <cylinder>
                <radius>0.02</radius>
                <length>1</length>
              </cylinder>
            </geometry>
            <material>
              <script>
                <uri>file://media/materials/scripts/gazebo.material</uri>
                <name>Gazebo/Grey</name>
              </script>
            </material>
          </visual>
          <collision name='back_left_leg'>
            <pose>-0.68 0.38 0.5 0 -0 0</pose>
            <geometry>
              <cylinder>
                <radius>0.02</radius>
                <length>1</length>
              </cylinder>
            </geometry>
            <max_contacts>10</max_contacts>
            <surface>
              <contact>
                <ode/>
              </contact>
              <bounce/>
              <friction>
                <torsional>
                  <ode/>
                </torsional>
                <ode/>
              </friction>
            </surface>
          </collision>
          <visual name='back_left_leg'>
            <pose>-0.68 0.38 0.5 0 -0 0</pose>
            <geometry>
              <cylinder>
                <radius>0.02</radius>
                <length>1</length>
              </cylinder>
            </geometry>
            <material>
              <script>
                <uri>file://media/materials/scripts/gazebo.material</uri>
                <name>Gazebo/Grey</name>
              </script>
            </material>
          </visual>
          <self_collide>0</self_collide>
          <enable_wind>0</enable_wind>
          <kinematic>0</kinematic>
        </link>
        <pose>1.62877 -0.26315 -0.43905 0 -0 1.56526</pose>
      </model>
      <model name='table_0'>
        <static>1</static>
        <link name='link'>
          <collision name='surface'>
            <pose>0 0 1 0 -0 0</pose>
            <geometry>
              <box>
                <size>1.5 0.8 0.03</size>
              </box>
            </geometry>
            <surface>
              <friction>
                <ode>
                  <mu>0.6</mu>
                  <mu2>0.6</mu2>
                </ode>
                <torsional>
                  <ode/>
                </torsional>
              </friction>
              <contact>
                <ode/>
              </contact>
              <bounce/>
            </surface>
            <max_contacts>10</max_contacts>
          </collision>
          <visual name='visual1'>
            <pose>0 0 1 0 -0 0</pose>
            <geometry>
              <box>
                <size>1.5 0.8 0.03</size>
              </box>
            </geometry>
            <material>
              <script>
                <uri>file://media/materials/scripts/gazebo.material</uri>
                <name>Gazebo/Wood</name>
              </script>
            </material>
          </visual>
          <collision name='front_left_leg'>
            <pose>0.68 0.38 0.5 0 -0 0</pose>
            <geometry>
              <cylinder>
                <radius>0.02</radius>
                <length>1</length>
              </cylinder>
            </geometry>
            <max_contacts>10</max_contacts>
            <surface>
              <contact>
                <ode/>
              </contact>
              <bounce/>
              <friction>
                <torsional>
                  <ode/>
                </torsional>
                <ode/>
              </friction>
            </surface>
          </collision>
          <visual name='front_left_leg'>
            <pose>0.68 0.38 0.5 0 -0 0</pose>
            <geometry>
              <cylinder>
                <radius>0.02</radius>
                <length>1</length>
              </cylinder>
            </geometry>
            <material>
              <script>
                <uri>file://media/materials/scripts/gazebo.material</uri>
                <name>Gazebo/Grey</name>
              </script>
            </material>
          </visual>
          <collision name='front_right_leg'>
            <pose>0.68 -0.38 0.5 0 -0 0</pose>
            <geometry>
              <cylinder>
                <radius>0.02</radius>
                <length>1</length>
              </cylinder>
            </geometry>
            <max_contacts>10</max_contacts>
            <surface>
              <contact>
                <ode/>
              </contact>
              <bounce/>
              <friction>
                <torsional>
                  <ode/>
                </torsional>
                <ode/>
              </friction>
            </surface>
          </collision>
          <visual name='front_right_leg'>
            <pose>0.68 -0.38 0.5 0 -0 0</pose>
            <geometry>
              <cylinder>
                <radius>0.02</radius>
                <length>1</length>
              </cylinder>
            </geometry>
            <material>
              <script>
                <uri>file://media/materials/scripts/gazebo.material</uri>
                <name>Gazebo/Grey</name>
              </script>
            </material>
          </visual>
          <collision name='back_right_leg'>
            <pose>-0.68 -0.38 0.5 0 -0 0</pose>
            <geometry>
              <cylinder>
                <radius>0.02</radius>
                <length>1</length>
              </cylinder>
            </geometry>
            <max_contacts>10</max_contacts>
            <surface>
              <contact>
                <ode/>
              </contact>
              <bounce/>
              <friction>
                <torsional>
                  <ode/>
                </torsional>
                <ode/>
              </friction>
            </surface>
          </collision>
          <visual name='back_right_leg'>
            <pose>-0.68 -0.38 0.5 0 -0 0</pose>
            <geometry>
              <cylinder>
                <radius>0.02</radius>
                <length>1</length>
              </cylinder>
            </geometry>
            <material>
              <script>
                <uri>file://media/materials/scripts/gazebo.material</uri>
                <name>Gazebo/Grey</name>
              </script>
            </material>
          </visual>
          <collision name='back_left_leg'>
            <pose>-0.68 0.38 0.5 0 -0 0</pose>
            <geometry>
              <cylinder>
                <radius>0.02</radius>
                <length>1</length>
              </cylinder>
            </geometry>
            <max_contacts>10</max_contacts>
            <surface>
              <contact>
                <ode/>
              </contact>
              <bounce/>
              <friction>
                <torsional>
                  <ode/>
                </torsional>
                <ode/>
              </friction>
            </surface>
          </collision>
          <visual name='back_left_leg'>
            <pose>-0.68 0.38 0.5 0 -0 0</pose>
            <geometry>
              <cylinder>
                <radius>0.02</radius>
                <length>1</length>
              </cylinder>
            </geometry>
            <material>
              <script>
                <uri>file://media/materials/scripts/gazebo.material</uri>
                <name>Gazebo/Grey</name>
              </script>
            </material>
          </visual>
          <self_collide>0</self_collide>
          <enable_wind>0</enable_wind>
          <kinematic>0</kinematic>
        </link>
        <pose>0.052371 1.36 -0.43905 0 -0 0</pose>
      </model>
      <model name='table_1'>
        <static>1</static>
        <link name='link'>
          <collision name='surface'>
            <pose>0 0 1 0 -0 0</pose>
            <geometry>
              <box>
                <size>1.5 0.8 0.03</size>
              </box>
            </geometry>
            <surface>
              <friction>
                <ode>
                  <mu>0.6</mu>
                  <mu2>0.6</mu2>
                </ode>
                <torsional>
                  <ode/>
                </torsional>
              </friction>
              <contact>
                <ode/>
              </contact>
              <bounce/>
            </surface>
            <max_contacts>10</max_contacts>
          </collision>
          <visual name='visual1'>
            <pose>0 0 1 0 -0 0</pose>
            <geometry>
              <box>
                <size>1.5 0.8 0.03</size>
              </box>
            </geometry>
            <material>
              <script>
                <uri>file://media/materials/scripts/gazebo.material</uri>
                <name>Gazebo/Wood</name>
              </script>
            </material>
          </visual>
          <collision name='front_left_leg'>
            <pose>0.68 0.38 0.5 0 -0 0</pose>
            <geometry>
              <cylinder>
                <radius>0.02</radius>
                <length>1</length>
              </cylinder>
            </geometry>
            <max_contacts>10</max_contacts>
            <surface>
              <contact>
                <ode/>
              </contact>
              <bounce/>
              <friction>
                <torsional>
                  <ode/>
                </torsional>
                <ode/>
              </friction>
            </surface>
          </collision>
          <visual name='front_left_leg'>
            <pose>0.68 0.38 0.5 0 -0 0</pose>
            <geometry>
              <cylinder>
                <radius>0.02</radius>
                <length>1</length>
              </cylinder>
            </geometry>
            <material>
              <script>
                <uri>file://media/materials/scripts/gazebo.material</uri>
                <name>Gazebo/Grey</name>
              </script>
            </material>
          </visual>
          <collision name='front_right_leg'>
            <pose>0.68 -0.38 0.5 0 -0 0</pose>
            <geometry>
              <cylinder>
                <radius>0.02</radius>
                <length>1</length>
              </cylinder>
            </geometry>
            <max_contacts>10</max_contacts>
            <surface>
              <contact>
                <ode/>
              </contact>
              <bounce/>
              <friction>
                <torsional>
                  <ode/>
                </torsional>
                <ode/>
              </friction>
            </surface>
          </collision>
          <visual name='front_right_leg'>
            <pose>0.68 -0.38 0.5 0 -0 0</pose>
            <geometry>
              <cylinder>
                <radius>0.02</radius>
                <length>1</length>
              </cylinder>
            </geometry>
            <material>
              <script>
                <uri>file://media/materials/scripts/gazebo.material</uri>
                <name>Gazebo/Grey</name>
              </script>
            </material>
          </visual>
          <collision name='back_right_leg'>
            <pose>-0.68 -0.38 0.5 0 -0 0</pose>
            <geometry>
              <cylinder>
                <radius>0.02</radius>
                <length>1</length>
              </cylinder>
            </geometry>
            <max_contacts>10</max_contacts>
            <surface>
              <contact>
                <ode/>
              </contact>
              <bounce/>
              <friction>
                <torsional>
                  <ode/>
                </torsional>
                <ode/>
              </friction>
            </surface>
          </collision>
          <visual name='back_right_leg'>
            <pose>-0.68 -0.38 0.5 0 -0 0</pose>
            <geometry>
              <cylinder>
                <radius>0.02</radius>
                <length>1</length>
              </cylinder>
            </geometry>
            <material>
              <script>
                <uri>file://media/materials/scripts/gazebo.material</uri>
                <name>Gazebo/Grey</name>
              </script>
            </material>
          </visual>
          <collision name='back_left_leg'>
            <pose>-0.68 0.38 0.5 0 -0 0</pose>
            <geometry>
              <cylinder>
                <radius>0.02</radius>
                <length>1</length>
              </cylinder>
            </geometry>
            <max_contacts>10</max_contacts>
            <surface>
              <contact>
                <ode/>
              </contact>
              <bounce/>
              <friction>
                <torsional>
                  <ode/>
                </torsional>
                <ode/>
              </friction>
            </surface>
          </collision>
          <visual name='back_left_leg'>
            <pose>-0.68 0.38 0.5 0 -0 0</pose>
            <geometry>
              <cylinder>
                <radius>0.02</radius>
                <length>1</length>
              </cylinder>
            </geometry>
            <material>
              <script>
                <uri>file://media/materials/scripts/gazebo.material</uri>
                <name>Gazebo/Grey</name>
              </script>
            </material>
          </visual>
          <self_collide>0</self_collide>
          <enable_wind>0</enable_wind>
          <kinematic>0</kinematic>
        </link>
        <pose>0.035425 -1.82696 -0.43905 0 -0 0</pose>
      </model>
      <model name='table_2'>
        <static>1</static>
        <link name='link'>
          <collision name='surface'>
            <pose>0 0 1 0 -0 0</pose>
            <geometry>
              <box>
                <size>1.5 0.8 0.03</size>
              </box>
            </geometry>
            <surface>
              <friction>
                <ode>
                  <mu>0.6</mu>
                  <mu2>0.6</mu2>
                </ode>
                <torsional>
                  <ode/>
                </torsional>
              </friction>
              <contact>
                <ode/>
              </contact>
              <bounce/>
            </surface>
            <max_contacts>10</max_contacts>
          </collision>
          <visual name='visual1'>
            <pose>0 0 1 0 -0 0</pose>
            <geometry>
              <box>
                <size>1.5 0.8 0.03</size>
              </box>
            </geometry>
            <material>
              <script>
                <uri>file://media/materials/scripts/gazebo.material</uri>
                <name>Gazebo/Wood</name>
              </script>
            </material>
          </visual>
          <collision name='front_left_leg'>
            <pose>0.68 0.38 0.5 0 -0 0</pose>
            <geometry>
              <cylinder>
                <radius>0.02</radius>
                <length>1</length>
              </cylinder>
            </geometry>
            <max_contacts>10</max_contacts>
            <surface>
              <contact>
                <ode/>
              </contact>
              <bounce/>
              <friction>
                <torsional>
                  <ode/>
                </torsional>
                <ode/>
              </friction>
            </surface>
          </collision>
          <visual name='front_left_leg'>
            <pose>0.68 0.38 0.5 0 -0 0</pose>
            <geometry>
              <cylinder>
                <radius>0.02</radius>
                <length>1</length>
              </cylinder>
            </geometry>
            <material>
              <script>
                <uri>file://media/materials/scripts/gazebo.material</uri>
                <name>Gazebo/Grey</name>
              </script>
            </material>
          </visual>
          <collision name='front_right_leg'>
            <pose>0.68 -0.38 0.5 0 -0 0</pose>
            <geometry>
              <cylinder>
                <radius>0.02</radius>
                <length>1</length>
              </cylinder>
            </geometry>
            <max_contacts>10</max_contacts>
            <surface>
              <contact>
                <ode/>
              </contact>
              <bounce/>
              <friction>
                <torsional>
                  <ode/>
                </torsional>
                <ode/>
              </friction>
            </surface>
          </collision>
          <visual name='front_right_leg'>
            <pose>0.68 -0.38 0.5 0 -0 0</pose>
            <geometry>
              <cylinder>
                <radius>0.02</radius>
                <length>1</length>
              </cylinder>
            </geometry>
            <material>
              <script>
                <uri>file://media/materials/scripts/gazebo.material</uri>
                <name>Gazebo/Grey</name>
              </script>
            </material>
          </visual>
          <collision name='back_right_leg'>
            <pose>-0.68 -0.38 0.5 0 -0 0</pose>
            <geometry>
              <cylinder>
                <radius>0.02</radius>
                <length>1</length>
              </cylinder>
            </geometry>
            <max_contacts>10</max_contacts>
            <surface>
              <contact>
                <ode/>
              </contact>
              <bounce/>
              <friction>
                <torsional>
                  <ode/>
                </torsional>
                <ode/>
              </friction>
            </surface>
          </collision>
          <visual name='back_right_leg'>
            <pose>-0.68 -0.38 0.5 0 -0 0</pose>
            <geometry>
              <cylinder>
                <radius>0.02</radius>
                <length>1</length>
              </cylinder>
            </geometry>
            <material>
              <script>
                <uri>file://media/materials/scripts/gazebo.material</uri>
                <name>Gazebo/Grey</name>
              </script>
            </material>
          </visual>
          <collision name='back_left_leg'>
            <pose>-0.68 0.38 0.5 0 -0 0</pose>
            <geometry>
              <cylinder>
                <radius>0.02</radius>
                <length>1</length>
              </cylinder>
            </geometry>
            <max_contacts>10</max_contacts>
            <surface>
              <contact>
                <ode/>
              </contact>
              <bounce/>
              <friction>
                <torsional>
                  <ode/>
                </torsional>
                <ode/>
              </friction>
            </surface>
          </collision>
          <visual name='back_left_leg'>
            <pose>-0.68 0.38 0.5 0 -0 0</pose>
            <geometry>
              <cylinder>
                <radius>0.02</radius>
                <length>1</length>
              </cylinder>
            </geometry>
            <material>
              <script>
                <uri>file://media/materials/scripts/gazebo.material</uri>
                <name>Gazebo/Grey</name>
              </script>
            </material>
          </visual>
          <self_collide>0</self_collide>
          <enable_wind>0</enable_wind>
          <kinematic>0</kinematic>
        </link>
        <pose>-1.5381 -0.257927 -0.43905 0 0 -1.56447</pose>
      </model>
      <static>0</static>
      <allow_auto_disable>1</allow_auto_disable>
      <pose>-0.034477 0.236046 0.43905 0 -0 0</pose>
    </model>
    <state world_name='default'>
      <sim_time>355 384000000</sim_time>
      <real_time>304 456107028</real_time>
      <wall_time>1733338988 283863778</wall_time>
      <iterations>288262</iterations>
      <model name='Coffee_Shop_Model_V3'>
        <pose>-0.034477 0.23605 -407166 0 -0 0</pose>
        <scale>1 1 1</scale>
        <link name='link_0'>
          <pose>0.025456 1.48734 -407166 1.57072 -0.004244 -1.55352</pose>
          <velocity>0 0 -2824.97 0 -0 0</velocity>
          <acceleration>0 0 -9.8 0 -0 0</acceleration>
          <wrench>0 0 -9.8 0 -0 0</wrench>
        </link>
        <link name='link_1'>
          <pose>-1.56558 0.052598 -407166 1.56674 -0 0</pose>
          <velocity>0 0 -2824.97 0 -0 0</velocity>
          <acceleration>0 0 -9.8 0 -0 0</acceleration>
          <wrench>0 0 -9.8 0 -0 0</wrench>
        </link>
        <link name='link_2'>
          <pose>1.25822 0.156248 -407166 0 -0 0</pose>
          <velocity>0 0 -2824.97 0 -0 0</velocity>
          <acceleration>0 0 -9.8 0 -0 0</acceleration>
          <wrench>0 0 -9.8 0 -0 0</wrench>
        </link>
        <model name='table'>
          <pose>1.59429 -0.027104 0 0 -0 1.56526</pose>
          <scale>1 1 1</scale>
          <link name='link'>
            <pose>1.59429 -0.027104 0 0 -0 1.56526</pose>
            <velocity>0 0 0 0 -0 0</velocity>
            <acceleration>0 0 0 0 -0 0</acceleration>
            <wrench>0 0 0 0 -0 0</wrench>
          </link>
        </model>
        <model name='table_0'>
          <pose>0.017894 1.59605 0 0 -0 0</pose>
          <scale>1 1 1</scale>
          <link name='link'>
            <pose>0.017894 1.59605 0 0 -0 0</pose>
            <velocity>0 0 0 0 -0 0</velocity>
            <acceleration>0 0 0 0 -0 0</acceleration>
            <wrench>0 0 0 0 -0 0</wrench>
          </link>
        </model>
        <model name='table_1'>
          <pose>0.000948 -1.59091 0 0 -0 0</pose>
          <scale>1 1 1</scale>
          <link name='link'>
            <pose>0.000948 -1.59091 0 0 -0 0</pose>
            <velocity>0 0 0 0 -0 0</velocity>
            <acceleration>0 0 0 0 -0 0</acceleration>
            <wrench>0 0 0 0 -0 0</wrench>
          </link>
        </model>
        <model name='table_2'>
          <pose>-1.57258 -0.021881 0 0 0 -1.56447</pose>
          <scale>1 1 1</scale>
          <link name='link'>
            <pose>-1.57258 -0.021881 0 0 0 -1.56447</pose>
            <velocity>0 0 0 0 -0 0</velocity>
            <acceleration>0 0 0 0 -0 0</acceleration>
            <wrench>0 0 0 0 -0 0</wrench>
          </link>
        </model>
      </model>
      <model name='ambulance'>
        <pose>4.78084 -0.716227 0 0 -0 0</pose>
        <scale>1 1 1</scale>
        <link name='link'>
          <pose>4.78084 -0.716227 0 0 -0 0</pose>
          <velocity>0 0 0 0 -0 0</velocity>
          <acceleration>0 0 0 0 -0 0</acceleration>
          <wrench>0 0 0 0 -0 0</wrench>
        </link>
      </model>
      <model name='apartment'>
        <pose>-14.073 -0.994406 0 0 -0 0</pose>
        <scale>1 1 1</scale>
        <link name='link'>
          <pose>-14.073 -0.994406 0 0 -0 0</pose>
          <velocity>0 0 0 0 -0 0</velocity>
          <acceleration>0 0 0 0 -0 0</acceleration>
          <wrench>0 0 0 0 -0 0</wrench>
        </link>
      </model>
      <model name='brick_box_3x1x3'>
        <pose>0.274191 3.40283 0 0 -0 0</pose>
        <scale>1 1 1</scale>
        <link name='chassis'>
          <pose>0.274191 3.40283 1.5 0 -0 0</pose>
          <velocity>0 0 0 0 -0 0</velocity>
          <acceleration>0 0 0 0 -0 0</acceleration>
          <wrench>0 0 0 0 -0 0</wrench>
        </link>
      </model>
      <model name='ground_plane'>
        <pose>0 0 0 0 -0 0</pose>
        <scale>1 1 1</scale>
        <link name='link'>
          <pose>0 0 0 0 -0 0</pose>
          <velocity>0 0 0 0 -0 0</velocity>
          <acceleration>0 0 0 0 -0 0</acceleration>
          <wrench>0 0 0 0 -0 0</wrench>
        </link>
      </model>
      <model name='robot_name-0.05025905482986204'>
        <pose>-6e-06 2e-06 0.000813 1e-05 -6.2e-05 -0.499999</pose>
        <scale>1 1 1</scale>
        <link name='base_link'>
          <pose>-6e-06 2e-06 0.000813 1e-05 -6.2e-05 -0.499999</pose>
          <velocity>-2e-06 -8e-06 0.010014 0.00651 -0.002808 3.2e-05</velocity>
          <acceleration>-6.5536 -1.23316 140.928 -0.469526 -1.40667 -2.13118</acceleration>
          <wrench>-170.859 -32.1498 3674.13 0 -0 0</wrench>
        </link>
        <link name='left_finger_1'>
          <pose>0.028559 -0.351945 2.39893 3.13368 0.002242 -1.52258</pose>
          <velocity>8.44061 0.212596 -0.077828 0.787502 -0.457027 1.79292</velocity>
          <acceleration>-6.60809 -7.59918 138.548 0.320754 -1.03634 2.89607</acceleration>
          <wrench>-0.006608 -0.007599 0.138548 0 -0 0</wrench>
        </link>
        <link name='left_finger_2'>
          <pose>0.03169 -0.424173 2.39877 1.56291 0.00235 -1.51016</pose>
          <velocity>14.4706 0.253713 -0.134439 0.88917 -0.479712 1.67219</velocity>
          <acceleration>-3.507 -7.74682 138.276 2.75693 0.814482 -2.26392</acceleration>
          <wrench>-0.003507 -0.007747 0.138276 0 -0 0</wrench>
        </link>
        <link name='link_1'>
          <pose>0.008358 -0.002243 1.01281 1.57281 0.008308 -0.029555</pose>
          <velocity>-0.002775 -0.006823 0.009925 0.053382 -0.015513 -0.601708</velocity>
          <acceleration>-15.6541 -2.92975 140.727 3.09118 -0.998358 -2.07116</acceleration>
          <wrench>-0.156541 -0.029297 1.40727 0 -0 0</wrench>
        </link>
        <link name='link_2'>
          <pose>0.00833 -0.026537 1.09581 1.57279 0.006851 -0.029558</pose>
          <velocity>0.13389 -0.013203 0.008126 0.005971 -1.48311 -0.604603</velocity>
          <acceleration>-14.8215 -3.68391 139.964 2.2796 0.466132 0.463764</acceleration>
          <wrench>-0.148215 -0.036839 1.39964 0 -0 0</wrench>
        </link>
        <link name='link_3'>
          <pose>0.01249 -0.027869 1.7084 1.57283 0.010134 -0.029552</pose>
          <velocity>-0.767006 0.009181 0.015835 -3.02919 1.34271 2.54363</velocity>
          <acceleration>-14.4512 -5.95708 140.236 -1.85034 0.271074 -3.1226</acceleration>
          <wrench>-0.144512 -0.059571 1.40236 0 -0 0</wrench>
        </link>
        <link name='link_4'>
          <pose>0.018244 -0.029221 2.27993 1.57285 0.011211 -0.029549</pose>
          <velocity>0.268685 -0.025801 0.006765 -2.9946 0.276637 2.5458</velocity>
          <acceleration>-13.479 -7.05259 139.681 -3.05025 0.541334 2.0954</acceleration>
          <wrench>-0.13479 -0.070526 1.39681 0 -0 0</wrench>
        </link>
        <link name='link_5'>
          <pose>0.013832 -0.17924 2.28196 1.57299 0.011141 0.005167</pose>
          <velocity>1.1275 -0.059225 -0.002021 -2.65793 0.349374 -0.443387</velocity>
          <acceleration>-11.515 -7.52074 139.49 -2.76677 -1.39492 -2.03593</acceleration>
          <wrench>-0.11515 -0.075207 1.39489 0 -0 0</wrench>
        </link>
        <link name='link_6'>
          <pose>0.015172 -0.200595 2.39943 1.57267 0.007975 0.005161</pose>
          <velocity>2.3167 -0.152498 -0.01567 0.435814 -0.378922 2.69295</velocity>
          <acceleration>-9.52716 -7.66585 138.976 -1.54625 1.07897 -2.26861</acceleration>
          <wrench>-0.20007 -0.160983 2.91849 0 -0 0</wrench>
        </link>
        <link name='right_finger_1'>
          <pose>0.00306 -0.352057 2.39914 3.13368 0.002241 -1.52269</pose>
          <velocity>8.42423 -0.816774 -0.087304 0.786579 -0.456823 1.6815</velocity>
          <acceleration>-6.62565 -8.00884 138.574 0.302684 -1.03754 2.91088</acceleration>
          <wrench>-0.006626 -0.008009 0.138574 0 -0 0</wrench>
        </link>
        <link name='right_finger_2'>
          <pose>0.006184 -0.424283 2.39898 1.56291 0.002349 -1.51028</pose>
          <velocity>14.446 -0.776006 -0.143855 0.888149 -0.479481 1.54678</velocity>
          <acceleration>-3.52252 -8.17519 138.298 2.70576 0.811139 -2.2548</acceleration>
          <wrench>-0.003523 -0.008175 0.138298 0 -0 0</wrench>
        </link>
      </model>
      <model name='suv'>
        <pose>-0.110637 -3.65509 0 0 -0 0</pose>
        <scale>1 1 1</scale>
        <link name='link'>
          <pose>-0.110637 -3.65509 0 0 -0 0</pose>
          <velocity>0 0 0 0 -0 0</velocity>
          <acceleration>0 0 0 0 -0 0</acceleration>
          <wrench>0 0 0 0 -0 0</wrench>
        </link>
      </model>
      <light name='sun'>
        <pose>0 0 10 0 -0 0</pose>
      </light>
    </state>
    <model name='robot_name-0.05025905482986204'>
      <joint name='fixed_base' type='fixed'>
        <pose relative_to='__model__'>0 0 0 0 -0 0</pose>
        <parent>world</parent>
        <child>base_link</child>
      </joint>
      <link name='base_link'>
        <pose relative_to='fixed_base'>0 0 0 0 -0 0</pose>
        <inertial>
          <pose>0.003832 0.00093 0.457356 0 -0 0</pose>
          <mass>26.071</mass>
          <inertia>
            <ixx>1.88048</ixx>
            <ixy>-2.36037e-05</ixy>
            <ixz>-0.0147251</ixz>
            <iyy>1.88103</iyy>
            <iyz>-0.00352469</iyz>
            <izz>0.12331</izz>
          </inertia>
        </inertial>
        <collision name='base_link_collision'>
          <pose>0 0 0 0 -0 0</pose>
          <geometry>
            <mesh>
              <scale>1 1 1</scale>
              <uri>model://barista_robot/meshes/base_link.STL</uri>
            </mesh>
          </geometry>
          <surface>
            <contact>
              <ode/>
            </contact>
            <friction>
              <ode/>
              <torsional>
                <ode/>
              </torsional>
            </friction>
            <bounce/>
          </surface>
          <max_contacts>10</max_contacts>
        </collision>
        <collision name='base_link_fixed_joint_lump__robot_base_collision_1'>
          <pose>0.007647 0.001854 0.91276 1.5688 0.008376 -0.001107</pose>
          <geometry>
            <mesh>
              <scale>1 1 1</scale>
              <uri>model://barista_robot/meshes/robot_base.STL</uri>
            </mesh>
          </geometry>
          <surface>
            <contact>
              <ode/>
            </contact>
            <friction>
              <ode/>
              <torsional>
                <ode/>
              </torsional>
            </friction>
            <bounce/>
          </surface>
          <max_contacts>10</max_contacts>
        </collision>
        <visual name='base_link_visual'>
          <pose>0 0 0 0 -0 0</pose>
          <geometry>
            <mesh>
              <scale>1 1 1</scale>
              <uri>model://barista_robot/meshes/base_link.STL</uri>
            </mesh>
          </geometry>
          <material>
            <ambient>0.25098 0.25098 0.25098 1</ambient>
            <diffuse>0.25098 0.25098 0.25098 1</diffuse>
            <specular>0.1 0.1 0.1 1</specular>
            <emissive>0 0 0 0</emissive>
          </material>
        </visual>
        <visual name='base_link_fixed_joint_lump__robot_base_visual_1'>
          <pose>0.007647 0.001854 0.91276 1.5688 0.008376 -0.001107</pose>
          <geometry>
            <mesh>
              <scale>1 1 1</scale>
              <uri>model://barista_robot/meshes/robot_base.STL</uri>
            </mesh>
          </geometry>
          <material>
            <ambient>1 0.501961 0.501961 1</ambient>
            <diffuse>0.501961 0.501961 1 1</diffuse>
            <specular>0.1 0.1 0.1 1</specular>
            <emissive>0 0 0 0</emissive>
          </material>
        </visual>
        <self_collide>0</self_collide>
        <enable_wind>0</enable_wind>
        <kinematic>0</kinematic>
      </link>
      <joint name='link_1_joint' type='revolute'>
        <pose relative_to='base_link'>0.008479 0.002052 1.012 1.57278 0.00838 0.46476</pose>
        <parent>base_link</parent>
        <child>link_1</child>
        <axis>
          <xyz>0 1 0</xyz>
          <limit>
            <lower>-6.28</lower>
            <upper>6.28</upper>
            <effort>100</effort>
            <velocity>3.14</velocity>
          </limit>
          <dynamics>
            <spring_reference>0</spring_reference>
            <spring_stiffness>0</spring_stiffness>
          </dynamics>
        </axis>
      </joint>
      <link name='link_1'>
        <pose relative_to='link_1_joint'>0 0 0 0 -0 0</pose>
        <inertial>
          <pose>0 0.085043 0.012893 0 -0 0</pose>
          <mass>0.01</mass>
          <inertia>
            <ixx>0.0144417</ixx>
            <ixy>-1.76721e-07</ixy>
            <ixz>1.27034e-07</ixz>
            <iyy>0.0120176</iyy>
            <iyz>-0.000178585</iyz>
            <izz>0.0128349</izz>
          </inertia>
        </inertial>
        <collision name='link_1_collision'>
          <pose>0 0 0 0 -0 0</pose>
          <geometry>
            <mesh>
              <scale>1 1 1</scale>
              <uri>model://barista_robot/meshes/link_1.STL</uri>
            </mesh>
          </geometry>
          <surface>
            <contact>
              <ode/>
            </contact>
            <friction>
              <ode/>
              <torsional>
                <ode/>
              </torsional>
            </friction>
            <bounce/>
          </surface>
          <max_contacts>10</max_contacts>
        </collision>
        <visual name='link_1_visual'>
          <pose>0 0 0 0 -0 0</pose>
          <geometry>
            <mesh>
              <scale>1 1 1</scale>
              <uri>model://barista_robot/meshes/link_1.STL</uri>
            </mesh>
          </geometry>
          <material>
            <ambient>1 0.501961 0.501961 1</ambient>
            <diffuse>0.501961 0.501961 1 1</diffuse>
            <specular>0.1 0.1 0.1 1</specular>
            <emissive>0 0 0 0</emissive>
          </material>
        </visual>
        <self_collide>0</self_collide>
        <enable_wind>0</enable_wind>
        <kinematic>0</kinematic>
      </link>
      <joint name='link_2_joint' type='revolute'>
        <pose relative_to='link_1'>0 0.083054 0.024109 0 -0 0</pose>
        <parent>link_1</parent>
        <child>link_2</child>
        <axis>
          <xyz>0 0 1</xyz>
          <limit>
            <lower>-6.28</lower>
            <upper>6.28</upper>
            <effort>100</effort>
            <velocity>3.14</velocity>
          </limit>
          <dynamics>
            <spring_reference>0</spring_reference>
            <spring_stiffness>0</spring_stiffness>
          </dynamics>
        </axis>
      </joint>
      <link name='link_2'>
        <pose relative_to='link_2_joint'>0 0 0 0 -0 0</pose>
        <inertial>
          <pose>-2e-06 0.211231 0.152883 0 -0 0</pose>
          <mass>0.01</mass>
          <inertia>
            <ixx>0.421786</ixx>
            <ixy>-4.66699e-06</ixy>
            <ixz>-8.61934e-07</ixz>
            <iyy>0.0183913</iyy>
            <iyz>0.000922258</iyz>
            <izz>0.418871</izz>
          </inertia>
        </inertial>
        <collision name='link_2_collision'>
          <pose>0 0 0 0 -0 0</pose>
          <geometry>
            <mesh>
              <scale>1 1 1</scale>
              <uri>model://barista_robot/meshes/link_2.STL</uri>
            </mesh>
          </geometry>
          <surface>
            <contact>
              <ode/>
            </contact>
            <friction>
              <ode/>
              <torsional>
                <ode/>
              </torsional>
            </friction>
            <bounce/>
          </surface>
          <max_contacts>10</max_contacts>
        </collision>
        <visual name='link_2_visual'>
          <pose>0 0 0 0 -0 0</pose>
          <geometry>
            <mesh>
              <scale>1 1 1</scale>
              <uri>model://barista_robot/meshes/link_2.STL</uri>
            </mesh>
          </geometry>
          <material>
            <ambient>1 0.501961 0.501961 1</ambient>
            <diffuse>0.501961 0.501961 1 1</diffuse>
            <specular>0.1 0.1 0.1 1</specular>
            <emissive>0 0 0 0</emissive>
          </material>
        </visual>
        <self_collide>0</self_collide>
        <enable_wind>0</enable_wind>
        <kinematic>0</kinematic>
      </link>
      <joint name='link_3_joint' type='revolute'>
        <pose relative_to='link_2'>0 0.6126 0 0 -0 0</pose>
        <parent>link_2</parent>
        <child>link_3</child>
        <axis>
          <xyz>0 0 1</xyz>
          <limit>
            <lower>-6.28</lower>
            <upper>6.28</upper>
            <effort>100</effort>
            <velocity>3.14</velocity>
          </limit>
          <dynamics>
            <spring_reference>0</spring_reference>
            <spring_stiffness>0</spring_stiffness>
          </dynamics>
        </axis>
      </joint>
      <link name='link_3'>
        <pose relative_to='link_3_joint'>0 0 0 0 -0 0</pose>
        <inertial>
          <pose>2e-06 0.26581 0.02013 0 -0 0</pose>
          <mass>0.01</mass>
          <inertia>
            <ixx>0.198422</ixx>
            <ixy>4.85995e-06</ixy>
            <ixz>-1.51824e-07</ixz>
            <iyy>0.00626605</iyy>
            <iyz>0.00588107</iyz>
            <izz>0.197534</izz>
          </inertia>
        </inertial>
        <collision name='link_3_collision'>
          <pose>0 0 0 0 -0 0</pose>
          <geometry>
            <mesh>
              <scale>1 1 1</scale>
              <uri>model://barista_robot/meshes/link_3.STL</uri>
            </mesh>
          </geometry>
          <surface>
            <contact>
              <ode/>
            </contact>
            <friction>
              <ode/>
              <torsional>
                <ode/>
              </torsional>
            </friction>
            <bounce/>
          </surface>
          <max_contacts>10</max_contacts>
        </collision>
        <visual name='link_3_visual'>
          <pose>0 0 0 0 -0 0</pose>
          <geometry>
            <mesh>
              <scale>1 1 1</scale>
              <uri>model://barista_robot/meshes/link_3.STL</uri>
            </mesh>
          </geometry>
          <material>
            <ambient>1 0.501961 0.501961 1</ambient>
            <diffuse>0.501961 0.501961 1 1</diffuse>
            <specular>0.1 0.1 0.1 1</specular>
            <emissive>0 0 0 0</emissive>
          </material>
        </visual>
        <self_collide>0</self_collide>
        <enable_wind>0</enable_wind>
        <kinematic>0</kinematic>
      </link>
      <joint name='link_4_joint' type='revolute'>
        <pose relative_to='link_3'>0 0.57155 0 0 -0 0</pose>
        <parent>link_3</parent>
        <child>link_4</child>
        <axis>
          <xyz>0 0 1</xyz>
          <limit>
            <lower>-6.28</lower>
            <upper>6.28</upper>
            <effort>100</effort>
            <velocity>3.14</velocity>
          </limit>
          <dynamics>
            <spring_reference>0</spring_reference>
            <spring_stiffness>0</spring_stiffness>
          </dynamics>
        </axis>
      </joint>
      <link name='link_4'>
        <pose relative_to='link_4_joint'>0 0 0 0 -0 0</pose>
        <inertial>
          <pose>-2e-06 0.00154 0.134078 0 -0 0</pose>
          <mass>0.01</mass>
          <inertia>
            <ixx>0.00181788</ixx>
            <ixy>1.83031e-08</ixy>
            <ixz>-2.837e-08</ixz>
            <iyy>0.00150426</iyy>
            <iyz>-4.60371e-05</iyz>
            <izz>0.00132307</izz>
          </inertia>
        </inertial>
        <collision name='link_4_collision'>
          <pose>0 0 0 0 -0 0</pose>
          <geometry>
            <mesh>
              <scale>1 1 1</scale>
              <uri>model://barista_robot/meshes/link_4.STL</uri>
            </mesh>
          </geometry>
          <surface>
            <contact>
              <ode/>
            </contact>
            <friction>
              <ode/>
              <torsional>
                <ode/>
              </torsional>
            </friction>
            <bounce/>
          </surface>
          <max_contacts>10</max_contacts>
        </collision>
        <visual name='link_4_visual'>
          <pose>0 0 0 0 -0 0</pose>
          <geometry>
            <mesh>
              <scale>1 1 1</scale>
              <uri>model://barista_robot/meshes/link_4.STL</uri>
            </mesh>
          </geometry>
          <material>
            <ambient>1 0.501961 0.501961 1</ambient>
            <diffuse>0.501961 0.501961 1 1</diffuse>
            <specular>0.1 0.1 0.1 1</specular>
            <emissive>0 0 0 0</emissive>
          </material>
        </visual>
        <self_collide>0</self_collide>
        <enable_wind>0</enable_wind>
        <kinematic>0</kinematic>
      </link>
      <joint name='link_5_joint' type='revolute'>
        <pose relative_to='link_4'>0 0.002332 0.15004 0 -0 0</pose>
        <parent>link_4</parent>
        <child>link_5</child>
        <axis>
          <xyz>0 1 0</xyz>
          <limit>
            <lower>-6.28</lower>
            <upper>6.28</upper>
            <effort>100</effort>
            <velocity>3.14</velocity>
          </limit>
          <dynamics>
            <spring_reference>0</spring_reference>
            <spring_stiffness>0</spring_stiffness>
          </dynamics>
        </axis>
      </joint>
      <link name='link_5'>
        <pose relative_to='link_5_joint'>0 0 0 0 -0 0</pose>
        <inertial>
          <pose>0 0.107895 0.001725 0 -0 0</pose>
          <mass>0.01</mass>
          <inertia>
            <ixx>0.00143476</ixx>
            <ixy>-5.38094e-09</ixy>
            <ixz>4.87204e-10</ixz>
            <iyy>0.00122173</iyy>
            <iyz>-3.67653e-05</iyz>
            <izz>0.00112163</izz>
          </inertia>
        </inertial>
        <collision name='link_5_collision'>
          <pose>0 0 0 0 -0 0</pose>
          <geometry>
            <mesh>
              <scale>1 1 1</scale>
              <uri>model://barista_robot/meshes/link_5.STL</uri>
            </mesh>
          </geometry>
          <surface>
            <contact>
              <ode/>
            </contact>
            <friction>
              <ode/>
              <torsional>
                <ode/>
              </torsional>
            </friction>
            <bounce/>
          </surface>
          <max_contacts>10</max_contacts>
        </collision>
        <visual name='link_5_visual'>
          <pose>0 0 0 0 -0 0</pose>
          <geometry>
            <mesh>
              <scale>1 1 1</scale>
              <uri>model://barista_robot/meshes/link_5.STL</uri>
            </mesh>
          </geometry>
          <material>
            <ambient>1 0.501961 0.501961 1</ambient>
            <diffuse>0.501961 0.501961 1 1</diffuse>
            <specular>0.1 0.1 0.1 1</specular>
            <emissive>0 0 0 0</emissive>
          </material>
        </visual>
        <self_collide>0</self_collide>
        <enable_wind>0</enable_wind>
        <kinematic>0</kinematic>
      </link>
      <joint name='link_6_joint' type='revolute'>
        <pose relative_to='link_5'>0 0.11752 0.020667 0 -0 0</pose>
        <parent>link_5</parent>
        <child>link_6</child>
        <axis>
          <xyz>0 0 1</xyz>
          <limit>
            <lower>-6.28</lower>
            <upper>6.28</upper>
            <effort>100</effort>
            <velocity>3.14</velocity>
          </limit>
          <dynamics>
            <spring_reference>0</spring_reference>
            <spring_stiffness>0</spring_stiffness>
          </dynamics>
        </axis>
      </joint>
      <link name='link_6'>
        <pose relative_to='link_6_joint'>0 0 0 0 -0 0</pose>
        <inertial>
          <pose>0 0.002125 0.090886 0 -0 0</pose>
          <mass>0.021</mass>
          <inertia>
            <ixx>0.000459626</ixx>
            <ixy>8.61368e-09</ixy>
            <ixz>-5.07777e-10</ixz>
            <iyy>0.00048391</iyy>
            <iyz>1.55123e-06</iyz>
            <izz>0.000483759</izz>
          </inertia>
        </inertial>
        <collision name='link_6_collision'>
          <pose>0 0 0 0 -0 0</pose>
          <geometry>
            <mesh>
              <scale>1 1 1</scale>
              <uri>model://barista_robot/meshes/link_6.STL</uri>
            </mesh>
          </geometry>
          <surface>
            <contact>
              <ode/>
            </contact>
            <friction>
              <ode/>
              <torsional>
                <ode/>
              </torsional>
            </friction>
            <bounce/>
          </surface>
          <max_contacts>10</max_contacts>
        </collision>
        <collision name='link_6_fixed_joint_lump__camera_link_collision_1'>
          <pose>0 0.0415 0.060233 -1 0 0</pose>
          <geometry>
            <mesh>
              <scale>1 1 1</scale>
              <uri>model://barista_robot/meshes/camera_link.STL</uri>
            </mesh>
          </geometry>
          <surface>
            <contact>
              <ode/>
            </contact>
            <friction>
              <ode/>
              <torsional>
                <ode/>
              </torsional>
            </friction>
            <bounce/>
          </surface>
          <max_contacts>10</max_contacts>
        </collision>
        <collision name='link_6_fixed_joint_lump__gripper_base_link_collision_2'>
          <pose>0.000288 -0.000107 0.089124 1.5708 -0 3.14159</pose>
          <geometry>
            <mesh>
              <scale>1 1 1</scale>
              <uri>model://barista_robot/meshes/gripper_base_link.STL</uri>
            </mesh>
          </geometry>
          <surface>
            <contact>
              <ode/>
            </contact>
            <friction>
              <ode/>
              <torsional>
                <ode/>
              </torsional>
            </friction>
            <bounce/>
          </surface>
          <max_contacts>10</max_contacts>
        </collision>
        <visual name='link_6_visual'>
          <pose>0 0 0 0 -0 0</pose>
          <geometry>
            <mesh>
              <scale>1 1 1</scale>
              <uri>model://barista_robot/meshes/link_6.STL</uri>
            </mesh>
          </geometry>
          <material>
            <ambient>1 0.501961 0.501961 1</ambient>
            <diffuse>0.501961 0.501961 1 1</diffuse>
            <specular>0.1 0.1 0.1 1</specular>
            <emissive>0 0 0 0</emissive>
          </material>
        </visual>
        <visual name='link_6_fixed_joint_lump__camera_link_visual_1'>
          <pose>0 0.0415 0.060233 -1 0 0</pose>
          <geometry>
            <mesh>
              <scale>1 1 1</scale>
              <uri>model://barista_robot/meshes/camera_link.STL</uri>
            </mesh>
          </geometry>
          <material>
            <ambient>0.25098 0.25098 0.25098 1</ambient>
            <diffuse>0.25098 0.25098 0.25098 1</diffuse>
            <specular>0.1 0.1 0.1 1</specular>
            <emissive>0 0 0 0</emissive>
          </material>
        </visual>
        <visual name='link_6_fixed_joint_lump__gripper_base_link_visual_2'>
          <pose>0.000288 -0.000107 0.089124 1.5708 -0 3.14159</pose>
          <geometry>
            <mesh>
              <scale>1 1 1</scale>
              <uri>model://barista_robot/meshes/gripper_base_link.STL</uri>
            </mesh>
          </geometry>
          <material>
            <ambient>1 0.501961 0.501961 1</ambient>
            <diffuse>0.501961 0.501961 1 1</diffuse>
            <specular>0.1 0.1 0.1 1</specular>
            <emissive>0 0 0 0</emissive>
          </material>
        </visual>
        <sensor name='camera_sensor' type='camera'>
          <camera>
            <horizontal_fov>1.047</horizontal_fov>
            <image>
              <width>640</width>
              <height>480</height>
              <format>R8G8B8</format>
            </image>
            <clip>
              <near>0.01</near>
              <far>100</far>
            </clip>
          </camera>
          <plugin name='camera_controller' filename='libgazebo_ros_camera.so'>
            <ros>
              <namespace>/camera</namespace>
              <argument>--ros-args</argument>
            </ros>
            <update_rate>30.0</update_rate>
            <image_topic_name>image_raw</image_topic_name>
            <camera_info_topic_name>camera_info</camera_info_topic_name>
          </plugin>
          <pose>0 0.0415 0.060233 -1 0 0</pose>
        </sensor>
        <self_collide>0</self_collide>
        <enable_wind>0</enable_wind>
        <kinematic>0</kinematic>
      </link>
      <joint name='left_finger_1_joint' type='revolute'>
        <pose relative_to='link_6'>0.0127 -0.000107 0.150561 0.785391 -1.57079 0.785391</pose>
        <parent>link_6</parent>
        <child>left_finger_1</child>
        <axis>
          <xyz>0 0 1</xyz>
          <limit>
            <lower>-3.14</lower>
            <upper>3.14</upper>
            <effort>100</effort>
            <velocity>3.14</velocity>
          </limit>
          <dynamics>
            <spring_reference>0</spring_reference>
            <spring_stiffness>0</spring_stiffness>
          </dynamics>
        </axis>
      </joint>
      <link name='left_finger_1'>
        <pose relative_to='left_finger_1_joint'>0 0 0 0 -0 0</pose>
        <inertial>
          <pose>0.036226 0 -4.2e-05 0 -0 0</pose>
          <mass>0.001</mass>
          <inertia>
            <ixx>6.64067e-06</ixx>
            <ixy>-5.31597e-14</ixy>
            <ixz>-1.58102e-14</ixz>
            <iyy>1.70446e-05</iyy>
            <iyz>1.13977e-11</iyz>
            <izz>1.11318e-05</izz>
          </inertia>
        </inertial>
        <collision name='left_finger_1_collision'>
          <pose>0 0 0 0 -0 0</pose>
          <geometry>
            <mesh>
              <scale>1 1 1</scale>
              <uri>model://barista_robot/meshes/left_finger_1.STL</uri>
            </mesh>
          </geometry>
          <surface>
            <contact>
              <ode/>
            </contact>
            <friction>
              <ode/>
              <torsional>
                <ode/>
              </torsional>
            </friction>
            <bounce/>
          </surface>
          <max_contacts>10</max_contacts>
        </collision>
        <visual name='left_finger_1_visual'>
          <pose>0 0 0 0 -0 0</pose>
          <geometry>
            <mesh>
              <scale>1 1 1</scale>
              <uri>model://barista_robot/meshes/left_finger_1.STL</uri>
            </mesh>
          </geometry>
          <material>
            <ambient>1 0.501961 0.501961 1</ambient>
            <diffuse>0.501961 0.501961 1 1</diffuse>
            <specular>0.1 0.1 0.1 1</specular>
            <emissive>0 0 0 0</emissive>
          </material>
        </visual>
        <self_collide>0</self_collide>
        <enable_wind>0</enable_wind>
        <kinematic>0</kinematic>
      </link>
      <joint name='left_finger_2_joint' type='revolute'>
        <pose relative_to='left_finger_1'>0.071343 0 0 -1.5708 0 0</pose>
        <parent>left_finger_1</parent>
        <child>left_finger_2</child>
        <axis>
          <xyz>0 1 0</xyz>
          <limit>
            <lower>-3.14</lower>
            <upper>3.14</upper>
            <effort>100</effort>
            <velocity>3.14</velocity>
          </limit>
          <dynamics>
            <spring_reference>0</spring_reference>
            <spring_stiffness>0</spring_stiffness>
          </dynamics>
        </axis>
      </joint>
      <link name='left_finger_2'>
        <pose relative_to='left_finger_2_joint'>0 0 0 0 -0 0</pose>
        <inertial>
          <pose>0.020561 0.000122 -0 0 -0 0</pose>
          <mass>0.001</mass>
          <inertia>
            <ixx>2.63348e-07</ixx>
            <ixy>1.21659e-13</ixy>
            <ixz>-2.86603e-14</ixz>
            <iyy>1.51983e-06</iyy>
            <iyz>1.85155e-13</iyz>
            <izz>1.68463e-06</izz>
          </inertia>
        </inertial>
        <collision name='left_finger_2_collision'>
          <pose>0 0 0 0 -0 0</pose>
          <geometry>
            <mesh>
              <scale>1 1 1</scale>
              <uri>model://barista_robot/meshes/left_finger_2.STL</uri>
            </mesh>
          </geometry>
          <surface>
            <contact>
              <ode/>
            </contact>
            <friction>
              <ode/>
              <torsional>
                <ode/>
              </torsional>
            </friction>
            <bounce/>
          </surface>
          <max_contacts>10</max_contacts>
        </collision>
        <visual name='left_finger_2_visual'>
          <pose>0 0 0 0 -0 0</pose>
          <geometry>
            <mesh>
              <scale>1 1 1</scale>
              <uri>model://barista_robot/meshes/left_finger_2.STL</uri>
            </mesh>
          </geometry>
          <material>
            <ambient>1 0.501961 0.501961 1</ambient>
            <diffuse>0.501961 0.501961 1 1</diffuse>
            <specular>0.1 0.1 0.1 1</specular>
            <emissive>0 0 0 0</emissive>
          </material>
        </visual>
        <self_collide>0</self_collide>
        <enable_wind>0</enable_wind>
        <kinematic>0</kinematic>
      </link>
      <joint name='right_finger_1_joint' type='revolute'>
        <pose relative_to='link_6'>-0.0127 -0.000107 0.150561 0.785391 -1.57079 0.785391</pose>
        <parent>link_6</parent>
        <child>right_finger_1</child>
        <axis>
          <xyz>0 0 1</xyz>
          <limit>
            <lower>-3.14</lower>
            <upper>3.14</upper>
            <effort>100</effort>
            <velocity>3.14</velocity>
          </limit>
          <dynamics>
            <spring_reference>0</spring_reference>
            <spring_stiffness>0</spring_stiffness>
          </dynamics>
        </axis>
      </joint>
      <link name='right_finger_1'>
        <pose relative_to='right_finger_1_joint'>0 0 0 0 -0 0</pose>
        <inertial>
          <pose>0.036226 0 -4.2e-05 0 -0 0</pose>
          <mass>0.001</mass>
          <inertia>
            <ixx>6.64067e-06</ixx>
            <ixy>-5.31597e-14</ixy>
            <ixz>-1.58101e-14</ixz>
            <iyy>1.70446e-05</iyy>
            <iyz>1.13977e-11</iyz>
            <izz>1.11318e-05</izz>
          </inertia>
        </inertial>
        <collision name='right_finger_1_collision'>
          <pose>0 0 0 0 -0 0</pose>
          <geometry>
            <mesh>
              <scale>1 1 1</scale>
              <uri>model://barista_robot/meshes/right_finger_1.STL</uri>
            </mesh>
          </geometry>
          <surface>
            <contact>
              <ode/>
            </contact>
            <friction>
              <ode/>
              <torsional>
                <ode/>
              </torsional>
            </friction>
            <bounce/>
          </surface>
          <max_contacts>10</max_contacts>
        </collision>
        <visual name='right_finger_1_visual'>
          <pose>0 0 0 0 -0 0</pose>
          <geometry>
            <mesh>
              <scale>1 1 1</scale>
              <uri>model://barista_robot/meshes/right_finger_1.STL</uri>
            </mesh>
          </geometry>
          <material>
            <ambient>1 0.501961 0.501961 1</ambient>
            <diffuse>0.501961 0.501961 1 1</diffuse>
            <specular>0.1 0.1 0.1 1</specular>
            <emissive>0 0 0 0</emissive>
          </material>
        </visual>
        <self_collide>0</self_collide>
        <enable_wind>0</enable_wind>
        <kinematic>0</kinematic>
      </link>
      <joint name='right_finger_2_joint' type='revolute'>
        <pose relative_to='right_finger_1'>0.071343 0 0 -1.5708 0 0</pose>
        <parent>right_finger_1</parent>
        <child>right_finger_2</child>
        <axis>
          <xyz>0 1 0</xyz>
          <limit>
            <lower>-3.14</lower>
            <upper>3.14</upper>
            <effort>100</effort>
            <velocity>3.14</velocity>
          </limit>
          <dynamics>
            <spring_reference>0</spring_reference>
            <spring_stiffness>0</spring_stiffness>
          </dynamics>
        </axis>
      </joint>
      <link name='right_finger_2'>
        <pose relative_to='right_finger_2_joint'>0 0 0 0 -0 0</pose>
        <inertial>
          <pose>0.020561 0.000122 -0 0 -0 0</pose>
          <mass>0.001</mass>
          <inertia>
            <ixx>2.63348e-07</ixx>
            <ixy>1.21659e-13</ixy>
            <ixz>-2.86603e-14</ixz>
            <iyy>1.51983e-06</iyy>
            <iyz>1.85155e-13</iyz>
            <izz>1.68463e-06</izz>
          </inertia>
        </inertial>
        <collision name='right_finger_2_collision'>
          <pose>0 0 0 0 -0 0</pose>
          <geometry>
            <mesh>
              <scale>1 1 1</scale>
              <uri>model://barista_robot/meshes/right_finger_2.STL</uri>
            </mesh>
          </geometry>
          <surface>
            <contact>
              <ode/>
            </contact>
            <friction>
              <ode/>
              <torsional>
                <ode/>
              </torsional>
            </friction>
            <bounce/>
          </surface>
          <max_contacts>10</max_contacts>
        </collision>
        <visual name='right_finger_2_visual'>
          <pose>0 0 0 0 -0 0</pose>
          <geometry>
            <mesh>
              <scale>1 1 1</scale>
              <uri>model://barista_robot/meshes/right_finger_2.STL</uri>
            </mesh>
          </geometry>
          <material>
            <ambient>1 0.501961 0.501961 1</ambient>
            <diffuse>0.501961 0.501961 1 1</diffuse>
            <specular>0.1 0.1 0.1 1</specular>
            <emissive>0 0 0 0</emissive>
          </material>
        </visual>
        <self_collide>0</self_collide>
        <enable_wind>0</enable_wind>
        <kinematic>0</kinematic>
      </link>
      <static>0</static>
      <plugin name='gazebo_ros2_control' filename='libgazebo_ros2_control.so'>
        <parameters>/home/manas/ros2_ws/install/barista_robot/share/barista_robot/config/control.yaml</parameters>
      </plugin>
      <pose>0 0 0 0 0 -0.5</pose>
    </model>
    <model name='suv'>
      <static>1</static>
      <link name='link'>
        <collision name='collision'>
          <pose>0 0 0 0 0 -1.5708</pose>
          <geometry>
            <mesh>
              <scale>0.06 0.06 0.06</scale>
              <uri>model://suv/meshes/suv.obj</uri>
            </mesh>
          </geometry>
          <max_contacts>10</max_contacts>
          <surface>
            <contact>
              <ode/>
            </contact>
            <bounce/>
            <friction>
              <torsional>
                <ode/>
              </torsional>
              <ode/>
            </friction>
          </surface>
        </collision>
        <visual name='visual'>
          <pose>0 0 0 0 0 -1.5708</pose>
          <geometry>
            <mesh>
              <scale>0.06 0.06 0.06</scale>
              <uri>model://suv/meshes/suv.obj</uri>
            </mesh>
          </geometry>
        </visual>
        <self_collide>0</self_collide>
        <enable_wind>0</enable_wind>
        <kinematic>0</kinematic>
      </link>
      <pose>-0.110637 -3.65509 0 0 -0 0</pose>
    </model>
    <model name='ambulance'>
      <static>1</static>
      <link name='link'>
        <collision name='collision'>
          <geometry>
            <mesh>
              <scale>0.0254 0.0254 0.0254</scale>
              <uri>model://ambulance/meshes/ambulance.obj</uri>
            </mesh>
          </geometry>
          <max_contacts>10</max_contacts>
          <surface>
            <contact>
              <ode/>
            </contact>
            <bounce/>
            <friction>
              <torsional>
                <ode/>
              </torsional>
              <ode/>
            </friction>
          </surface>
        </collision>
        <visual name='visual'>
          <geometry>
            <mesh>
              <scale>0.0254 0.0254 0.0254</scale>
              <uri>model://ambulance/meshes/ambulance.obj</uri>
            </mesh>
          </geometry>
        </visual>
        <self_collide>0</self_collide>
        <enable_wind>0</enable_wind>
        <kinematic>0</kinematic>
      </link>
      <pose>4.78084 -0.716227 0 0 -0 0</pose>
    </model>
    <model name='brick_box_3x1x3'>
      <static>1</static>
      <link name='chassis'>
        <pose>0 0 1.5 0 -0 0</pose>
        <collision name='collision'>
          <geometry>
            <box>
              <size>3 1 3</size>
            </box>
          </geometry>
          <max_contacts>10</max_contacts>
          <surface>
            <contact>
              <ode/>
            </contact>
            <bounce/>
            <friction>
              <torsional>
                <ode/>
              </torsional>
              <ode/>
            </friction>
          </surface>
        </collision>
        <visual name='visual'>
          <geometry>
            <mesh>
              <uri>model://brick_box_3x1x3/meshes/simple_box.dae</uri>
              <scale>3 1 3</scale>
            </mesh>
          </geometry>
          <material>
            <script>
              <uri>model://brick_box_3x1x3/materials/scripts</uri>
              <uri>model://brick_box_3x1x3/materials/textures</uri>
              <name>BrickBox/Diffuse</name>
            </script>
          </material>
        </visual>
        <self_collide>0</self_collide>
        <enable_wind>0</enable_wind>
        <kinematic>0</kinematic>
      </link>
      <pose>-0.180828 3.40926 0 0 -0 0</pose>
    </model>
    <model name='apartment'>
      <static>1</static>
      <link name='link'>
        <collision name='collision'>
          <geometry>
            <mesh>
              <uri>model://apartment/meshes/apartment.dae</uri>
            </mesh>
          </geometry>
          <max_contacts>10</max_contacts>
          <surface>
            <contact>
              <ode/>
            </contact>
            <bounce/>
            <friction>
              <torsional>
                <ode/>
              </torsional>
              <ode/>
            </friction>
          </surface>
        </collision>
        <visual name='visual'>
          <geometry>
            <mesh>
              <uri>model://apartment/meshes/apartment.dae</uri>
            </mesh>
          </geometry>
        </visual>
        <self_collide>0</self_collide>
        <enable_wind>0</enable_wind>
        <kinematic>0</kinematic>
      </link>
      <pose>-17.3216 -0.994406 0 0 -0 0</pose>
    </model>
  </world>
</sdf>
